[2024-03-17T13:12:16.108+0000] {taskinstance.py:1979} INFO - Dependencies all met for dep_context=non-requeueable deps ti=<TaskInstance: application_record_processing.read_csv manual__2024-03-17T13:12:14.199440+00:00 [queued]>
[2024-03-17T13:12:16.118+0000] {taskinstance.py:1979} INFO - Dependencies all met for dep_context=requeueable deps ti=<TaskInstance: application_record_processing.read_csv manual__2024-03-17T13:12:14.199440+00:00 [queued]>
[2024-03-17T13:12:16.119+0000] {taskinstance.py:2193} INFO - Starting attempt 1 of 1
[2024-03-17T13:12:16.132+0000] {taskinstance.py:2217} INFO - Executing <Task(PythonOperator): read_csv> on 2024-03-17 13:12:14.199440+00:00
[2024-03-17T13:12:16.138+0000] {standard_task_runner.py:60} INFO - Started process 164 to run task
[2024-03-17T13:12:16.141+0000] {standard_task_runner.py:87} INFO - Running: ['***', 'tasks', 'run', 'application_record_processing', 'read_csv', 'manual__2024-03-17T13:12:14.199440+00:00', '--job-id', '32', '--raw', '--subdir', 'DAGS_FOLDER/etl.py', '--cfg-path', '/tmp/tmppv6ycv12']
[2024-03-17T13:12:16.142+0000] {standard_task_runner.py:88} INFO - Job 32: Subtask read_csv
[2024-03-17T13:12:16.188+0000] {task_command.py:423} INFO - Running <TaskInstance: application_record_processing.read_csv manual__2024-03-17T13:12:14.199440+00:00 [running]> on host 6cb0e4687a92
[2024-03-17T13:12:16.264+0000] {taskinstance.py:2513} INFO - Exporting env vars: AIRFLOW_CTX_DAG_OWNER='***' AIRFLOW_CTX_DAG_ID='application_record_processing' AIRFLOW_CTX_TASK_ID='read_csv' AIRFLOW_CTX_EXECUTION_DATE='2024-03-17T13:12:14.199440+00:00' AIRFLOW_CTX_TRY_NUMBER='1' AIRFLOW_CTX_DAG_RUN_ID='manual__2024-03-17T13:12:14.199440+00:00'
[2024-03-17T13:12:16.265+0000] {taskinstance.py:2731} ERROR - Task failed with exception
Traceback (most recent call last):
  File "/home/airflow/.local/lib/python3.8/site-packages/airflow/models/taskinstance.py", line 444, in _execute_task
    result = _execute_callable(context=context, **execute_callable_kwargs)
  File "/home/airflow/.local/lib/python3.8/site-packages/airflow/models/taskinstance.py", line 414, in _execute_callable
    return execute_callable(context=context, **execute_callable_kwargs)
  File "/home/airflow/.local/lib/python3.8/site-packages/airflow/operators/python.py", line 200, in execute
    return_value = self.execute_callable()
  File "/home/airflow/.local/lib/python3.8/site-packages/airflow/operators/python.py", line 217, in execute_callable
    return self.python_callable(*self.op_args, **self.op_kwargs)
  File "/opt/airflow/dags/etl.py", line 10, in read_csv
    current_dir = os.path.dirname(__file__)
NameError: name 'os' is not defined
[2024-03-17T13:12:16.277+0000] {taskinstance.py:1149} INFO - Marking task as FAILED. dag_id=application_record_processing, task_id=read_csv, execution_date=20240317T131214, start_date=20240317T131216, end_date=20240317T131216
[2024-03-17T13:12:16.289+0000] {standard_task_runner.py:107} ERROR - Failed to execute job 32 for task read_csv (name 'os' is not defined; 164)
[2024-03-17T13:12:16.313+0000] {local_task_job_runner.py:234} INFO - Task exited with return code 1
[2024-03-17T13:12:16.340+0000] {taskinstance.py:3312} INFO - 0 downstream tasks scheduled from follow-on schedule check
