[2024-03-17T12:20:01.776+0000] {taskinstance.py:1979} INFO - Dependencies all met for dep_context=non-requeueable deps ti=<TaskInstance: application_record_processing.read_csv scheduled__2024-03-17T12:15:00+00:00 [queued]>
[2024-03-17T12:20:01.784+0000] {taskinstance.py:1979} INFO - Dependencies all met for dep_context=requeueable deps ti=<TaskInstance: application_record_processing.read_csv scheduled__2024-03-17T12:15:00+00:00 [queued]>
[2024-03-17T12:20:01.785+0000] {taskinstance.py:2193} INFO - Starting attempt 1 of 1
[2024-03-17T12:20:01.796+0000] {taskinstance.py:2217} INFO - Executing <Task(PythonOperator): read_csv> on 2024-03-17 12:15:00+00:00
[2024-03-17T12:20:01.802+0000] {standard_task_runner.py:60} INFO - Started process 121 to run task
[2024-03-17T12:20:01.805+0000] {standard_task_runner.py:87} INFO - Running: ['***', 'tasks', 'run', 'application_record_processing', 'read_csv', 'scheduled__2024-03-17T12:15:00+00:00', '--job-id', '6', '--raw', '--subdir', 'DAGS_FOLDER/etl.py', '--cfg-path', '/tmp/tmpsvswdp1u']
[2024-03-17T12:20:01.806+0000] {standard_task_runner.py:88} INFO - Job 6: Subtask read_csv
[2024-03-17T12:20:01.856+0000] {task_command.py:423} INFO - Running <TaskInstance: application_record_processing.read_csv scheduled__2024-03-17T12:15:00+00:00 [running]> on host 48b60e62f057
[2024-03-17T12:20:01.919+0000] {taskinstance.py:2513} INFO - Exporting env vars: AIRFLOW_CTX_DAG_OWNER='***' AIRFLOW_CTX_DAG_ID='application_record_processing' AIRFLOW_CTX_TASK_ID='read_csv' AIRFLOW_CTX_EXECUTION_DATE='2024-03-17T12:15:00+00:00' AIRFLOW_CTX_TRY_NUMBER='1' AIRFLOW_CTX_DAG_RUN_ID='scheduled__2024-03-17T12:15:00+00:00'
[2024-03-17T12:20:01.922+0000] {taskinstance.py:2731} ERROR - Task failed with exception
Traceback (most recent call last):
  File "/home/airflow/.local/lib/python3.8/site-packages/airflow/models/taskinstance.py", line 444, in _execute_task
    result = _execute_callable(context=context, **execute_callable_kwargs)
  File "/home/airflow/.local/lib/python3.8/site-packages/airflow/models/taskinstance.py", line 414, in _execute_callable
    return execute_callable(context=context, **execute_callable_kwargs)
  File "/home/airflow/.local/lib/python3.8/site-packages/airflow/operators/python.py", line 200, in execute
    return_value = self.execute_callable()
  File "/home/airflow/.local/lib/python3.8/site-packages/airflow/operators/python.py", line 217, in execute_callable
    return self.python_callable(*self.op_args, **self.op_kwargs)
  File "/opt/airflow/dags/etl.py", line 11, in read_csv
    df = pd.read_csv(csv_file)
  File "/home/airflow/.local/lib/python3.8/site-packages/pandas/io/parsers/readers.py", line 912, in read_csv
    return _read(filepath_or_buffer, kwds)
  File "/home/airflow/.local/lib/python3.8/site-packages/pandas/io/parsers/readers.py", line 577, in _read
    parser = TextFileReader(filepath_or_buffer, **kwds)
  File "/home/airflow/.local/lib/python3.8/site-packages/pandas/io/parsers/readers.py", line 1407, in __init__
    self._engine = self._make_engine(f, self.engine)
  File "/home/airflow/.local/lib/python3.8/site-packages/pandas/io/parsers/readers.py", line 1661, in _make_engine
    self.handles = get_handle(
  File "/home/airflow/.local/lib/python3.8/site-packages/pandas/io/common.py", line 859, in get_handle
    handle = open(
FileNotFoundError: [Errno 2] No such file or directory: '/airflow/application_record.csv'
[2024-03-17T12:20:01.933+0000] {taskinstance.py:1149} INFO - Marking task as FAILED. dag_id=application_record_processing, task_id=read_csv, execution_date=20240317T121500, start_date=20240317T122001, end_date=20240317T122001
[2024-03-17T12:20:01.945+0000] {standard_task_runner.py:107} ERROR - Failed to execute job 6 for task read_csv ([Errno 2] No such file or directory: '/airflow/application_record.csv'; 121)
[2024-03-17T12:20:01.978+0000] {local_task_job_runner.py:234} INFO - Task exited with return code 1
[2024-03-17T12:20:02.001+0000] {taskinstance.py:3312} INFO - 0 downstream tasks scheduled from follow-on schedule check
