[2024-03-17T12:24:54.886+0000] {taskinstance.py:1979} INFO - Dependencies all met for dep_context=non-requeueable deps ti=<TaskInstance: application_record_processing.save_data scheduled__2024-03-17T12:15:00+00:00 [queued]>
[2024-03-17T12:24:54.897+0000] {taskinstance.py:1979} INFO - Dependencies all met for dep_context=requeueable deps ti=<TaskInstance: application_record_processing.save_data scheduled__2024-03-17T12:15:00+00:00 [queued]>
[2024-03-17T12:24:54.898+0000] {taskinstance.py:2193} INFO - Starting attempt 1 of 1
[2024-03-17T12:24:54.912+0000] {taskinstance.py:2217} INFO - Executing <Task(PythonOperator): save_data> on 2024-03-17 12:15:00+00:00
[2024-03-17T12:24:54.917+0000] {standard_task_runner.py:60} INFO - Started process 202 to run task
[2024-03-17T12:24:54.920+0000] {standard_task_runner.py:87} INFO - Running: ['***', 'tasks', 'run', 'application_record_processing', 'save_data', 'scheduled__2024-03-17T12:15:00+00:00', '--job-id', '9', '--raw', '--subdir', 'DAGS_FOLDER/etl.py', '--cfg-path', '/tmp/tmpo9uxxvtg']
[2024-03-17T12:24:54.921+0000] {standard_task_runner.py:88} INFO - Job 9: Subtask save_data
[2024-03-17T12:24:54.971+0000] {task_command.py:423} INFO - Running <TaskInstance: application_record_processing.save_data scheduled__2024-03-17T12:15:00+00:00 [running]> on host 48b60e62f057
[2024-03-17T12:24:55.036+0000] {taskinstance.py:2513} INFO - Exporting env vars: AIRFLOW_CTX_DAG_OWNER='***' AIRFLOW_CTX_DAG_ID='application_record_processing' AIRFLOW_CTX_TASK_ID='save_data' AIRFLOW_CTX_EXECUTION_DATE='2024-03-17T12:15:00+00:00' AIRFLOW_CTX_TRY_NUMBER='1' AIRFLOW_CTX_DAG_RUN_ID='scheduled__2024-03-17T12:15:00+00:00'
[2024-03-17T12:24:55.038+0000] {taskinstance.py:2731} ERROR - Task failed with exception
Traceback (most recent call last):
  File "/home/airflow/.local/lib/python3.8/site-packages/airflow/models/taskinstance.py", line 444, in _execute_task
    result = _execute_callable(context=context, **execute_callable_kwargs)
  File "/home/airflow/.local/lib/python3.8/site-packages/airflow/models/taskinstance.py", line 414, in _execute_callable
    return execute_callable(context=context, **execute_callable_kwargs)
  File "/home/airflow/.local/lib/python3.8/site-packages/airflow/operators/python.py", line 200, in execute
    return_value = self.execute_callable()
  File "/home/airflow/.local/lib/python3.8/site-packages/airflow/operators/python.py", line 217, in execute_callable
    return self.python_callable(*self.op_args, **self.op_kwargs)
TypeError: save_data() missing 1 required positional argument: 'df'
[2024-03-17T12:24:55.046+0000] {taskinstance.py:1149} INFO - Marking task as FAILED. dag_id=application_record_processing, task_id=save_data, execution_date=20240317T121500, start_date=20240317T122454, end_date=20240317T122455
[2024-03-17T12:24:55.059+0000] {standard_task_runner.py:107} ERROR - Failed to execute job 9 for task save_data (save_data() missing 1 required positional argument: 'df'; 202)
[2024-03-17T12:24:55.093+0000] {local_task_job_runner.py:234} INFO - Task exited with return code 1
[2024-03-17T12:24:55.113+0000] {taskinstance.py:3312} INFO - 0 downstream tasks scheduled from follow-on schedule check
