[2024-03-17T12:24:44.117+0000] {taskinstance.py:1979} INFO - Dependencies all met for dep_context=non-requeueable deps ti=<TaskInstance: application_record_processing.cleanse_null_data scheduled__2024-03-17T12:15:00+00:00 [queued]>
[2024-03-17T12:24:44.127+0000] {taskinstance.py:1979} INFO - Dependencies all met for dep_context=requeueable deps ti=<TaskInstance: application_record_processing.cleanse_null_data scheduled__2024-03-17T12:15:00+00:00 [queued]>
[2024-03-17T12:24:44.128+0000] {taskinstance.py:2193} INFO - Starting attempt 1 of 1
[2024-03-17T12:24:44.140+0000] {taskinstance.py:2217} INFO - Executing <Task(PythonOperator): cleanse_null_data> on 2024-03-17 12:15:00+00:00
[2024-03-17T12:24:44.146+0000] {standard_task_runner.py:60} INFO - Started process 199 to run task
[2024-03-17T12:24:44.149+0000] {standard_task_runner.py:87} INFO - Running: ['***', 'tasks', 'run', 'application_record_processing', 'cleanse_null_data', 'scheduled__2024-03-17T12:15:00+00:00', '--job-id', '8', '--raw', '--subdir', 'DAGS_FOLDER/etl.py', '--cfg-path', '/tmp/tmp5w0asf4g']
[2024-03-17T12:24:44.151+0000] {standard_task_runner.py:88} INFO - Job 8: Subtask cleanse_null_data
[2024-03-17T12:24:44.199+0000] {task_command.py:423} INFO - Running <TaskInstance: application_record_processing.cleanse_null_data scheduled__2024-03-17T12:15:00+00:00 [running]> on host 48b60e62f057
[2024-03-17T12:24:44.270+0000] {taskinstance.py:2513} INFO - Exporting env vars: AIRFLOW_CTX_DAG_OWNER='***' AIRFLOW_CTX_DAG_ID='application_record_processing' AIRFLOW_CTX_TASK_ID='cleanse_null_data' AIRFLOW_CTX_EXECUTION_DATE='2024-03-17T12:15:00+00:00' AIRFLOW_CTX_TRY_NUMBER='1' AIRFLOW_CTX_DAG_RUN_ID='scheduled__2024-03-17T12:15:00+00:00'
[2024-03-17T12:24:44.272+0000] {taskinstance.py:2731} ERROR - Task failed with exception
Traceback (most recent call last):
  File "/home/airflow/.local/lib/python3.8/site-packages/airflow/models/taskinstance.py", line 444, in _execute_task
    result = _execute_callable(context=context, **execute_callable_kwargs)
  File "/home/airflow/.local/lib/python3.8/site-packages/airflow/models/taskinstance.py", line 414, in _execute_callable
    return execute_callable(context=context, **execute_callable_kwargs)
  File "/home/airflow/.local/lib/python3.8/site-packages/airflow/operators/python.py", line 200, in execute
    return_value = self.execute_callable()
  File "/home/airflow/.local/lib/python3.8/site-packages/airflow/operators/python.py", line 217, in execute_callable
    return self.python_callable(*self.op_args, **self.op_kwargs)
TypeError: cleanse_null_data() missing 1 required positional argument: 'df'
[2024-03-17T12:24:44.282+0000] {taskinstance.py:1149} INFO - Marking task as FAILED. dag_id=application_record_processing, task_id=cleanse_null_data, execution_date=20240317T121500, start_date=20240317T122444, end_date=20240317T122444
[2024-03-17T12:24:44.292+0000] {standard_task_runner.py:107} ERROR - Failed to execute job 8 for task cleanse_null_data (cleanse_null_data() missing 1 required positional argument: 'df'; 199)
[2024-03-17T12:24:44.322+0000] {local_task_job_runner.py:234} INFO - Task exited with return code 1
[2024-03-17T12:24:44.344+0000] {taskinstance.py:3312} INFO - 0 downstream tasks scheduled from follow-on schedule check
