[2024-03-17T13:38:03.911+0000] {taskinstance.py:1979} INFO - Dependencies all met for dep_context=non-requeueable deps ti=<TaskInstance: application_record_processing.format_standardization manual__2024-03-17T13:27:50.351934+00:00 [queued]>
[2024-03-17T13:38:03.920+0000] {taskinstance.py:1979} INFO - Dependencies all met for dep_context=requeueable deps ti=<TaskInstance: application_record_processing.format_standardization manual__2024-03-17T13:27:50.351934+00:00 [queued]>
[2024-03-17T13:38:03.921+0000] {taskinstance.py:2193} INFO - Starting attempt 2 of 2
[2024-03-17T13:38:03.932+0000] {taskinstance.py:2217} INFO - Executing <Task(PythonOperator): format_standardization> on 2024-03-17 13:27:50.351934+00:00
[2024-03-17T13:38:03.939+0000] {standard_task_runner.py:60} INFO - Started process 373 to run task
[2024-03-17T13:38:03.942+0000] {standard_task_runner.py:87} INFO - Running: ['***', 'tasks', 'run', 'application_record_processing', 'format_standardization', 'manual__2024-03-17T13:27:50.351934+00:00', '--job-id', '61', '--raw', '--subdir', 'DAGS_FOLDER/etl.py', '--cfg-path', '/tmp/tmppc3lbsvh']
[2024-03-17T13:38:03.944+0000] {standard_task_runner.py:88} INFO - Job 61: Subtask format_standardization
[2024-03-17T13:38:03.989+0000] {task_command.py:423} INFO - Running <TaskInstance: application_record_processing.format_standardization manual__2024-03-17T13:27:50.351934+00:00 [running]> on host cc537db63590
[2024-03-17T13:38:04.057+0000] {taskinstance.py:2513} INFO - Exporting env vars: AIRFLOW_CTX_DAG_OWNER='***' AIRFLOW_CTX_DAG_ID='application_record_processing' AIRFLOW_CTX_TASK_ID='format_standardization' AIRFLOW_CTX_EXECUTION_DATE='2024-03-17T13:27:50.351934+00:00' AIRFLOW_CTX_TRY_NUMBER='2' AIRFLOW_CTX_DAG_RUN_ID='manual__2024-03-17T13:27:50.351934+00:00'
[2024-03-17T13:38:04.059+0000] {taskinstance.py:2731} ERROR - Task failed with exception
Traceback (most recent call last):
  File "/home/airflow/.local/lib/python3.8/site-packages/airflow/models/taskinstance.py", line 444, in _execute_task
    result = _execute_callable(context=context, **execute_callable_kwargs)
  File "/home/airflow/.local/lib/python3.8/site-packages/airflow/models/taskinstance.py", line 414, in _execute_callable
    return execute_callable(context=context, **execute_callable_kwargs)
  File "/home/airflow/.local/lib/python3.8/site-packages/airflow/operators/python.py", line 200, in execute
    return_value = self.execute_callable()
  File "/home/airflow/.local/lib/python3.8/site-packages/airflow/operators/python.py", line 217, in execute_callable
    return self.python_callable(*self.op_args, **self.op_kwargs)
TypeError: format_standardization() missing 1 required positional argument: 'df'
[2024-03-17T13:38:04.066+0000] {taskinstance.py:1149} INFO - Marking task as FAILED. dag_id=application_record_processing, task_id=format_standardization, execution_date=20240317T132750, start_date=20240317T133803, end_date=20240317T133804
[2024-03-17T13:38:04.076+0000] {standard_task_runner.py:107} ERROR - Failed to execute job 61 for task format_standardization (format_standardization() missing 1 required positional argument: 'df'; 373)
[2024-03-17T13:38:04.114+0000] {local_task_job_runner.py:234} INFO - Task exited with return code 1
[2024-03-17T13:38:04.133+0000] {taskinstance.py:3312} INFO - 0 downstream tasks scheduled from follow-on schedule check
